<sdf version='1.9'>
  <world name='sensor_world'>
    <physics name='1ms' type='ignored'>
      <max_step_size>0.001</max_step_size>
      <real_time_factor>1</real_time_factor>
      <real_time_update_rate>1000</real_time_update_rate>
    </physics>
    <plugin name='ignition::gazebo::systems::Physics' filename='ignition-gazebo-physics-system'/>
    <plugin name='ignition::gazebo::systems::UserCommands' filename='ignition-gazebo-user-commands-system'/>
    <plugin name='ignition::gazebo::systems::SceneBroadcaster' filename='ignition-gazebo-scene-broadcaster-system'/>
    <plugin name='ignition::gazebo::systems::Imu' filename='ignition-gazebo-imu-system'/>
    <plugin name='ignition::gazebo::systems::Sensors' filename='ignition-gazebo-sensors-system'>
      <render_engine>ogre2</render_engine>
    </plugin>
    <plugin name='ignition::gazebo::systems::Contact' filename='ignition-gazebo-contact-system'/>
    <gui fullscreen='false'>
      <plugin name='3D View' filename='MinimalScene'>
        <gz-gui>
          <title>3D View</title>
          <property type='bool' key='showTitleBar'>false</property>
          <property type='string' key='state'>docked</property>
        </gz-gui>
        <engine>ogre2</engine>
        <scene>scene</scene>
        <ambient_light>0.4 0.4 0.4</ambient_light>
        <background_color>0.8 0.8 0.8</background_color>
        <camera_pose>-6 0 6 0 0.5 0</camera_pose>
        <camera_clip>
          <near>0.25</near>
          <far>25000</far>
        </camera_clip>
      </plugin>
      <plugin name='Entity context menu' filename='EntityContextMenuPlugin'>
        <gz-gui>
          <property key='state' type='string'>floating</property>
          <property key='width' type='double'>5</property>
          <property key='height' type='double'>5</property>
          <property key='showTitleBar' type='bool'>false</property>
        </gz-gui>
      </plugin>
      <plugin name='Scene Manager' filename='GzSceneManager'>
        <gz-gui>
          <property key='resizable' type='bool'>false</property>
          <property key='width' type='double'>5</property>
          <property key='height' type='double'>5</property>
          <property key='state' type='string'>floating</property>
          <property key='showTitleBar' type='bool'>false</property>
        </gz-gui>
      </plugin>
      <plugin name='Interactive view control' filename='InteractiveViewControl'>
        <gz-gui>
          <property key='resizable' type='bool'>false</property>
          <property key='width' type='double'>5</property>
          <property key='height' type='double'>5</property>
          <property key='state' type='string'>floating</property>
          <property key='showTitleBar' type='bool'>false</property>
        </gz-gui>
      </plugin>
      <plugin name='Camera Tracking' filename='CameraTracking'>
        <gz-gui>
          <property key='resizable' type='bool'>false</property>
          <property key='width' type='double'>5</property>
          <property key='height' type='double'>5</property>
          <property key='state' type='string'>floating</property>
          <property key='showTitleBar' type='bool'>false</property>
        </gz-gui>
      </plugin>
      <plugin name='Marker manager' filename='MarkerManager'>
        <gz-gui>
          <property key='resizable' type='bool'>false</property>
          <property key='width' type='double'>5</property>
          <property key='height' type='double'>5</property>
          <property key='state' type='string'>floating</property>
          <property key='showTitleBar' type='bool'>false</property>
        </gz-gui>
      </plugin>
      <plugin name='Select Entities' filename='SelectEntities'>
        <gz-gui>
          <anchors target='Select entities'>
            <line own='right' target='right'/>
            <line own='top' target='top'/>
          </anchors>
          <property key='resizable' type='bool'>false</property>
          <property key='width' type='double'>5</property>
          <property key='height' type='double'>5</property>
          <property key='state' type='string'>floating</property>
          <property key='showTitleBar' type='bool'>false</property>
        </gz-gui>
      </plugin>
      <plugin name='Visualization Capabilities' filename='VisualizationCapabilities'>
        <gz-gui>
          <property key='resizable' type='bool'>false</property>
          <property key='width' type='double'>5</property>
          <property key='height' type='double'>5</property>
          <property key='state' type='string'>floating</property>
          <property key='showTitleBar' type='bool'>false</property>
        </gz-gui>
      </plugin>
      <plugin name='Spawn Entities' filename='Spawn'>
        <gz-gui>
          <anchors target='Select entities'>
            <line own='right' target='right'/>
            <line own='top' target='top'/>
          </anchors>
          <property key='resizable' type='bool'>false</property>
          <property key='width' type='double'>5</property>
          <property key='height' type='double'>5</property>
          <property key='state' type='string'>floating</property>
          <property key='showTitleBar' type='bool'>false</property>
        </gz-gui>
      </plugin>
      <plugin name='World control' filename='WorldControl'>
        <gz-gui>
          <title>World control</title>
          <property type='bool' key='showTitleBar'>false</property>
          <property type='bool' key='resizable'>false</property>
          <property type='double' key='height'>72</property>
          <property type='double' key='width'>121</property>
          <property type='double' key='z'>1</property>
          <property type='string' key='state'>floating</property>
          <anchors target='3D View'>
            <line own='left' target='left'/>
            <line own='bottom' target='bottom'/>
          </anchors>
        </gz-gui>
        <play_pause>true</play_pause>
        <step>true</step>
        <start_paused>true</start_paused>
        <use_event>true</use_event>
      </plugin>
      <plugin name='World stats' filename='WorldStats'>
        <gz-gui>
          <title>World stats</title>
          <property type='bool' key='showTitleBar'>false</property>
          <property type='bool' key='resizable'>false</property>
          <property type='double' key='height'>110</property>
          <property type='double' key='width'>290</property>
          <property type='double' key='z'>1</property>
          <property type='string' key='state'>floating</property>
          <anchors target='3D View'>
            <line own='right' target='right'/>
            <line own='bottom' target='bottom'/>
          </anchors>
        </gz-gui>
        <sim_time>true</sim_time>
        <real_time>true</real_time>
        <real_time_factor>true</real_time_factor>
        <iterations>true</iterations>
      </plugin>
      <plugin name='Shapes' filename='Shapes'>
        <gz-gui>
          <property key='resizable' type='bool'>false</property>
          <property key='x' type='double'>0</property>
          <property key='y' type='double'>0</property>
          <property key='width' type='double'>250</property>
          <property key='height' type='double'>50</property>
          <property key='state' type='string'>floating</property>
          <property key='showTitleBar' type='bool'>false</property>
          <property key='cardBackground' type='string'>#666666</property>
        </gz-gui>
      </plugin>
      <plugin name='Lights' filename='Lights'>
        <gz-gui>
          <property key='resizable' type='bool'>false</property>
          <property key='x' type='double'>250</property>
          <property key='y' type='double'>0</property>
          <property key='width' type='double'>150</property>
          <property key='height' type='double'>50</property>
          <property key='state' type='string'>floating</property>
          <property key='showTitleBar' type='bool'>false</property>
          <property key='cardBackground' type='string'>#666666</property>
        </gz-gui>
      </plugin>
      <plugin name='Transform control' filename='TransformControl'>
        <gz-gui>
          <property key='resizable' type='bool'>false</property>
          <property key='x' type='double'>0</property>
          <property key='y' type='double'>50</property>
          <property key='width' type='double'>250</property>
          <property key='height' type='double'>50</property>
          <property key='state' type='string'>floating</property>
          <property key='showTitleBar' type='bool'>false</property>
          <property key='cardBackground' type='string'>#777777</property>
        </gz-gui>
      </plugin>
      <plugin name='Screenshot' filename='Screenshot'>
        <gz-gui>
          <property key='resizable' type='bool'>false</property>
          <property key='x' type='double'>250</property>
          <property key='y' type='double'>50</property>
          <property key='width' type='double'>50</property>
          <property key='height' type='double'>50</property>
          <property key='state' type='string'>floating</property>
          <property key='showTitleBar' type='bool'>false</property>
          <property key='cardBackground' type='string'>#777777</property>
        </gz-gui>
      </plugin>
      <plugin name='VideoRecorder' filename='VideoRecorder'>
        <gz-gui>
          <property key='resizable' type='bool'>false</property>
          <property key='x' type='double'>300</property>
          <property key='y' type='double'>50</property>
          <property key='width' type='double'>50</property>
          <property key='height' type='double'>50</property>
          <property key='state' type='string'>floating</property>
          <property key='showTitleBar' type='bool'>false</property>
          <property key='cardBackground' type='string'>#777777</property>
        </gz-gui>
        <record_video>
          <use_sim_time>true</use_sim_time>
          <lockstep>false</lockstep>
          <bitrate>4000000</bitrate>
        </record_video>
      </plugin>
      <plugin name='Component inspector' filename='ComponentInspector'>
        <gz-gui>
          <property type='string' key='state'>docked_collapsed</property>
        </gz-gui>
      </plugin>
      <plugin name='Entity tree' filename='EntityTree'>
        <gz-gui>
          <property type='string' key='state'>docked_collapsed</property>
        </gz-gui>
      </plugin>
      <plugin name='View angle' filename='ViewAngle'>
        <gz-gui>
          <property type='string' key='state'>docked_collapsed</property>
        </gz-gui>
      </plugin>
      <plugin name='Key Publisher' filename='KeyPublisher'/>
    </gui>
    <plugin name='ignition::gazebo::systems::TriggeredPublisher' filename='libignition-gazebo-triggered-publisher-system.so'>
      <input type='ignition.msgs.Int32' topic='/keyboard/keypress'>
        <match field='data'>87</match>
      </input>
      <output type='ignition.msgs.Twist' topic='/cmd_vel'>linear: {x: 1.0}, angular: {z: 0.00}</output>
    </plugin>
    <plugin name='ignition::gazebo::systems::TriggeredPublisher' filename='libignition-gazebo-triggered-publisher-system.so'>
      <input type='ignition.msgs.Int32' topic='/keyboard/keypress'>
        <match field='data'>68</match>
      </input>
      <output type='ignition.msgs.Twist' topic='/cmd_vel'>linear: {x: 0.0}, angular: {z: -1.0}</output>
    </plugin>
    <plugin name='ignition::gazebo::systems::TriggeredPublisher' filename='libignition-gazebo-triggered-publisher-system.so'>
      <input type='ignition.msgs.Int32' topic='/keyboard/keypress'>
        <match field='data'>83</match>
      </input>
      <output type='ignition.msgs.Twist' topic='/cmd_vel'>linear: {x: -1.0}, angular: {z: 0.0}</output>
    </plugin>
    <plugin name='ignition::gazebo::systems::TriggeredPublisher' filename='libignition-gazebo-triggered-publisher-system.so'>
      <input type='ignition.msgs.Int32' topic='/keyboard/keypress'>
        <match field='data'>65</match>
      </input>
      <output type='ignition.msgs.Twist' topic='/cmd_vel'>linear: {x: 0.0}, angular: {z: 0.1}</output>
    </plugin>
    <plugin name='ignition::gazebo::systems::Imu' filename='libignition-gazebo-imu-system.so'/>
    <gravity>0 0 -9.8</gravity>
    <magnetic_field>6e-06 2.3e-05 -4.2e-05</magnetic_field>
    <atmosphere type='adiabatic'/>
    <scene>
      <ambient>0.4 0.4 0.4 1</ambient>
      <background>0.7 0.7 0.7 1</background>
      <shadows>true</shadows>
    </scene>
    <model name='ground_plane'>
      <static>true</static>
      <link name='link'>
        <collision name='collision'>
          <geometry>
            <plane>
              <normal>0 0 1</normal>
              <size>1 1</size>
            </plane>
          </geometry>
          <surface>
            <friction>
              <ode/>
            </friction>
            <bounce/>
            <contact/>
          </surface>
        </collision>
        <visual name='visual'>
          <geometry>
            <plane>
              <normal>0 0 1</normal>
              <size>100 100</size>
            </plane>
          </geometry>
          <material>
            <ambient>0.8 0.8 0.8 1</ambient>
            <diffuse>0.8 0.8 0.8 1</diffuse>
            <specular>0.8 0.8 0.8 1</specular>
          </material>
        </visual>
        <pose>0 0 0 0 -0 0</pose>
        <inertial>
          <pose>0 0 0 0 -0 0</pose>
          <mass>1</mass>
          <inertia>
            <ixx>1</ixx>
            <ixy>0</ixy>
            <ixz>0</ixz>
            <iyy>1</iyy>
            <iyz>0</iyz>
            <izz>1</izz>
          </inertia>
        </inertial>
        <enable_wind>false</enable_wind>
      </link>
      <pose>0 0 0 0 -0 0</pose>
      <self_collide>false</self_collide>
    </model>
    <model name='wall'>
      <static>true</static>
      <pose>5 0 0 0 -0 0</pose>
      <link name='box'>
        <visual name='visual'>
          <geometry>
            <box>
              <size>0.5 10 2</size>
            </box>
          </geometry>
          <material>
            <ambient>0 0 1 1</ambient>
            <diffuse>0 0 1 1</diffuse>
            <specular>0 0 1 1</specular>
          </material>
        </visual>
        <collision name='collision'>
          <geometry>
            <box>
              <size>0.5 10 2</size>
            </box>
          </geometry>
          <surface>
            <friction>
              <ode/>
            </friction>
            <bounce/>
            <contact/>
          </surface>
        </collision>
        <sensor name='sensor_contact' type='contact'>
          <contact>
            <collision>collision</collision>
            <topic>__default_topic__</topic>
          </contact>
          <pose>0 0 0 0 -0 0</pose>
        </sensor>
        <pose>0 0 0 0 -0 0</pose>
        <inertial>
          <pose>0 0 0 0 -0 0</pose>
          <mass>1</mass>
          <inertia>
            <ixx>1</ixx>
            <ixy>0</ixy>
            <ixz>0</ixz>
            <iyy>1</iyy>
            <iyz>0</iyz>
            <izz>1</izz>
          </inertia>
        </inertial>
        <enable_wind>false</enable_wind>
      </link>
      <plugin name='ignition::gazebo::systems::TouchPlugin' filename='libignition-gazebo-touchplugin-system.so'>
        <target>vehicle_blue</target>
        <namespace>wall</namespace>
        <time>0.001</time>
        <enabled>true</enabled>
      </plugin>
      <self_collide>false</self_collide>
    </model>
    <model name='vehicle_blue' canonical_link='chassis'>
      <pose>0 0 0 0 -0 0</pose>
      <plugin name='ignition::gazebo::systems::DiffDrive' filename='libignition-gazebo-diff-drive-system.so'>
        <left_joint>left_wheel_joint</left_joint>
        <right_joint>right_wheel_joint</right_joint>
        <wheel_separation>1.2</wheel_separation>
        <wheel_radius>0.4</wheel_radius>
        <odom_publish_frequency>1</odom_publish_frequency>
        <topic>cmd_vel</topic>
      </plugin>
      <link name='chassis'>
        <pose>0.5 0 0.4 0 -0 0</pose>
        <inertial>
          <mass>1.14395</mass>
          <inertia>
            <ixx>0.095328999999999997</ixx>
            <ixy>0</ixy>
            <ixz>0</ixz>
            <iyy>0.38131700000000002</iyy>
            <iyz>0</iyz>
            <izz>0.47664600000000001</izz>
          </inertia>
          <pose>0 0 0 0 -0 0</pose>
        </inertial>
        <visual name='visual'>
          <geometry>
            <box>
              <size>2 1.2 0.05</size>
            </box>
          </geometry>
          <material>
            <ambient>0 0 1 1</ambient>
            <diffuse>0 0 1 1</diffuse>
            <specular>0 0 1 1</specular>
          </material>
        </visual>
        <collision name='collision'>
          <geometry>
            <box>
              <size>2 1.2 0.05</size>
            </box>
          </geometry>
          <surface>
            <friction>
              <ode/>
            </friction>
            <bounce/>
            <contact/>
          </surface>
        </collision>
        <sensor name='imu_sensor' type='imu'>
          <pose>0 0 0 0 -0 0</pose>
          <topic>imu</topic>
          <update_rate>1</update_rate>
          <enable_metrics>false</enable_metrics>
          <imu>
            <orientation_reference_frame>
              <localization>CUSTOM</localization>
              <custom_rpy>0 0 0</custom_rpy>
              <grav_dir_x>1 0 0</grav_dir_x>
            </orientation_reference_frame>
            <angular_velocity>
              <x>
                <noise type='none'>
                  <mean>0</mean>
                  <stddev>0</stddev>
                  <bias_mean>0</bias_mean>
                  <bias_stddev>0</bias_stddev>
                  <dynamic_bias_stddev>0</dynamic_bias_stddev>
                  <dynamic_bias_correlation_time>0</dynamic_bias_correlation_time>
                  <precision>0</precision>
                </noise>
              </x>
              <y>
                <noise type='none'>
                  <mean>0</mean>
                  <stddev>0</stddev>
                  <bias_mean>0</bias_mean>
                  <bias_stddev>0</bias_stddev>
                  <dynamic_bias_stddev>0</dynamic_bias_stddev>
                  <dynamic_bias_correlation_time>0</dynamic_bias_correlation_time>
                  <precision>0</precision>
                </noise>
              </y>
              <z>
                <noise type='none'>
                  <mean>0</mean>
                  <stddev>0</stddev>
                  <bias_mean>0</bias_mean>
                  <bias_stddev>0</bias_stddev>
                  <dynamic_bias_stddev>0</dynamic_bias_stddev>
                  <dynamic_bias_correlation_time>0</dynamic_bias_correlation_time>
                  <precision>0</precision>
                </noise>
              </z>
            </angular_velocity>
            <linear_acceleration>
              <x>
                <noise type='none'>
                  <mean>0</mean>
                  <stddev>0</stddev>
                  <bias_mean>0</bias_mean>
                  <bias_stddev>0</bias_stddev>
                  <dynamic_bias_stddev>0</dynamic_bias_stddev>
                  <dynamic_bias_correlation_time>0</dynamic_bias_correlation_time>
                  <precision>0</precision>
                </noise>
              </x>
              <y>
                <noise type='none'>
                  <mean>0</mean>
                  <stddev>0</stddev>
                  <bias_mean>0</bias_mean>
                  <bias_stddev>0</bias_stddev>
                  <dynamic_bias_stddev>0</dynamic_bias_stddev>
                  <dynamic_bias_correlation_time>0</dynamic_bias_correlation_time>
                  <precision>0</precision>
                </noise>
              </y>
              <z>
                <noise type='none'>
                  <mean>0</mean>
                  <stddev>0</stddev>
                  <bias_mean>0</bias_mean>
                  <bias_stddev>0</bias_stddev>
                  <dynamic_bias_stddev>0</dynamic_bias_stddev>
                  <dynamic_bias_correlation_time>0</dynamic_bias_correlation_time>
                  <precision>0</precision>
                </noise>
              </z>
            </linear_acceleration>
            <enable_orientation>true</enable_orientation>
          </imu>
        </sensor>
        <sensor name='gpu_lidar' type='gpu_lidar'>
          <pose>0.8 0 0.5 0 -0 0</pose>
          <topic>lidar</topic>
          <update_rate>10</update_rate>
          <enable_metrics>false</enable_metrics>
          <lidar>
            <scan>
              <horizontal>
                <samples>640</samples>
                <resolution>1</resolution>
                <min_angle>-1.3962600000000001</min_angle>
                <max_angle>1.3962600000000001</max_angle>
              </horizontal>
              <vertical>
                <samples>1</samples>
                <min_angle>0</min_angle>
                <max_angle>0</max_angle>
                <resolution>0.01</resolution>
              </vertical>
            </scan>
            <range>
              <min>0.080000000000000002</min>
              <max>10</max>
              <resolution>0.01</resolution>
            </range>
            <noise>
              <type>none</type>
              <mean>0</mean>
              <stddev>0</stddev>
            </noise>
            <visibility_mask>4294967295</visibility_mask>
          </lidar>
        </sensor>
        <enable_wind>false</enable_wind>
      </link>
      <link name='left_motor'>
        <pose>0.7 0.5 0.5 0 -0 0</pose>
        <inertial>
          <mass>0.5</mass>
          <inertia>
            <ixx>0.095328999999999997</ixx>
            <ixy>0</ixy>
            <ixz>0</ixz>
            <iyy>0.38131700000000002</iyy>
            <iyz>0</iyz>
            <izz>0.47664600000000001</izz>
          </inertia>
          <pose>0 0 0 0 -0 0</pose>
        </inertial>
        <visual name='visual'>
          <geometry>
            <box>
              <size>0.5 0.2 0.2</size>
            </box>
          </geometry>
          <material>
            <ambient>1 0 0 1</ambient>
            <diffuse>1 0 0 1</diffuse>
            <specular>1 0 0 1</specular>
          </material>
        </visual>
        <collision name='collision'>
          <geometry>
            <box>
              <size>0.5 0.2 0.2</size>
            </box>
          </geometry>
          <surface>
            <friction>
              <ode/>
            </friction>
            <bounce/>
            <contact/>
          </surface>
        </collision>
        <enable_wind>false</enable_wind>
      </link>
      <link name='right_motor'>
        <pose>0.7 -0.5 0.5 0 -0 0</pose>
        <inertial>
          <mass>0.5</mass>
          <inertia>
            <ixx>0.095328999999999997</ixx>
            <ixy>0</ixy>
            <ixz>0</ixz>
            <iyy>0.38131700000000002</iyy>
            <iyz>0</iyz>
            <izz>0.47664600000000001</izz>
          </inertia>
          <pose>0 0 0 0 -0 0</pose>
        </inertial>
        <visual name='visual'>
          <geometry>
            <box>
              <size>0.5 0.2 0.2</size>
            </box>
          </geometry>
          <material>
            <ambient>1 0 0 1</ambient>
            <diffuse>1 0 0 1</diffuse>
            <specular>1 0 0 1</specular>
          </material>
        </visual>
        <collision name='collision'>
          <geometry>
            <box>
              <size>0.5 0.2 0.2</size>
            </box>
          </geometry>
          <surface>
            <friction>
              <ode/>
            </friction>
            <bounce/>
            <contact/>
          </surface>
        </collision>
        <enable_wind>false</enable_wind>
      </link>
      <link name='left_wheel'>
        <pose>0.9 0.7 0.5 -1.5707 0 0</pose>
        <inertial>
          <mass>1</mass>
          <inertia>
            <ixx>0.043333000000000003</ixx>
            <ixy>0</ixy>
            <ixz>0</ixz>
            <iyy>0.043333000000000003</iyy>
            <iyz>0</iyz>
            <izz>0.080000000000000002</izz>
          </inertia>
          <pose>0 0 0 0 -0 0</pose>
        </inertial>
        <visual name='visual'>
          <geometry>
            <cylinder>
              <radius>0.315</radius>
              <length>0.20000000000000001</length>
            </cylinder>
          </geometry>
          <material>
            <ambient>1 0 0 1</ambient>
            <diffuse>1 0 0 1</diffuse>
            <specular>1 0 0 1</specular>
          </material>
        </visual>
        <collision name='collision'>
          <geometry>
            <cylinder>
              <radius>0.315</radius>
              <length>0.20000000000000001</length>
            </cylinder>
          </geometry>
          <surface>
            <friction>
              <ode/>
            </friction>
            <bounce/>
            <contact/>
          </surface>
        </collision>
        <enable_wind>false</enable_wind>
      </link>
      <link name='right_wheel'>
        <pose>0.9 -0.7 0.5 -1.5707 0 0</pose>
        <inertial>
          <mass>1</mass>
          <inertia>
            <ixx>0.043333000000000003</ixx>
            <ixy>0</ixy>
            <ixz>0</ixz>
            <iyy>0.043333000000000003</iyy>
            <iyz>0</iyz>
            <izz>0.080000000000000002</izz>
          </inertia>
          <pose>0 0 0 0 -0 0</pose>
        </inertial>
        <visual name='visual'>
          <geometry>
            <cylinder>
              <radius>0.315</radius>
              <length>0.20000000000000001</length>
            </cylinder>
          </geometry>
          <material>
            <ambient>1 0 0 1</ambient>
            <diffuse>1 0 0 1</diffuse>
            <specular>1 0 0 1</specular>
          </material>
        </visual>
        <collision name='collision'>
          <geometry>
            <cylinder>
              <radius>0.315</radius>
              <length>0.20000000000000001</length>
            </cylinder>
          </geometry>
          <surface>
            <friction>
              <ode/>
            </friction>
            <bounce/>
            <contact/>
          </surface>
        </collision>
        <enable_wind>false</enable_wind>
      </link>
      <frame name='caster_frame' attached_to='chassis'>
        <pose>-0.4 0 -0.1075 0 0 0</pose>
      </frame>
      <link name='caster'>
        <pose>0.1 0 0.2925 0 -0 0</pose>
        <inertial>
          <mass>1</mass>
          <inertia>
            <ixx>0.016</ixx>
            <ixy>0</ixy>
            <ixz>0</ixz>
            <iyy>0.016</iyy>
            <iyz>0</iyz>
            <izz>0.016</izz>
          </inertia>
          <pose>0 0 0 0 -0 0</pose>
        </inertial>
        <visual name='visual'>
          <geometry>
            <sphere>
              <radius>0.1075</radius>
            </sphere>
          </geometry>
          <material>
            <ambient>0 1 0 1</ambient>
            <diffuse>0 1 0 1</diffuse>
            <specular>0 1 0 1</specular>
          </material>
        </visual>
        <collision name='collision'>
          <geometry>
            <sphere>
              <radius>0.1075</radius>
            </sphere>
          </geometry>
          <surface>
            <friction>
              <ode/>
            </friction>
            <bounce/>
            <contact/>
          </surface>
        </collision>
        <enable_wind>false</enable_wind>
      </link>
      <frame name='lidar_frame' attached_to='chassis'>
        <pose>0.8 0 0.5 0 0 0</pose>
      </frame>
      <joint name='left_wheel_joint' type='revolute'>
        <pose>0 -0 0 0 -0 0</pose>
        <parent>left_motor</parent>
        <child>left_wheel</child>
        <axis>
          <xyz>0 9.6e-05 1</xyz>
          <limit>
            <lower>-1.7976900000000001e+308</lower>
            <upper>1.7976900000000001e+308</upper>
            <effort>inf</effort>
            <velocity>inf</velocity>
            <stiffness>100000000</stiffness>
            <dissipation>1</dissipation>
          </limit>
          <dynamics>
            <spring_reference>0</spring_reference>
            <spring_stiffness>0</spring_stiffness>
            <damping>0</damping>
            <friction>0</friction>
          </dynamics>
        </axis>
      </joint>
      <joint name='right_wheel_joint' type='revolute'>
        <pose>0 0 0 0 -0 0</pose>
        <parent>right_motor</parent>
        <child>right_wheel</child>
        <axis>
          <xyz>0 9.6e-05 1</xyz>
          <limit>
            <lower>-1.7976900000000001e+308</lower>
            <upper>1.7976900000000001e+308</upper>
            <effort>inf</effort>
            <velocity>inf</velocity>
            <stiffness>100000000</stiffness>
            <dissipation>1</dissipation>
          </limit>
          <dynamics>
            <spring_reference>0</spring_reference>
            <spring_stiffness>0</spring_stiffness>
            <damping>0</damping>
            <friction>0</friction>
          </dynamics>
        </axis>
      </joint>
      <joint name='right_motor_joint' type='revolute'>
        <pose>0 0 0 0 -0 0</pose>
        <parent>chassis</parent>
        <child>right_motor</child>
        <axis>
          <xyz>0 1 0</xyz>
          <limit>
            <lower>0</lower>
            <upper>0</upper>
            <effort>inf</effort>
            <velocity>inf</velocity>
            <stiffness>100000000</stiffness>
            <dissipation>1</dissipation>
          </limit>
          <dynamics>
            <spring_reference>0</spring_reference>
            <spring_stiffness>0</spring_stiffness>
            <damping>0</damping>
            <friction>0</friction>
          </dynamics>
        </axis>
      </joint>
      <joint name='left_motor_joint' type='revolute'>
        <pose>0 0 0 0 -0 0</pose>
        <parent>chassis</parent>
        <child>left_motor</child>
        <axis>
          <xyz>0 1 0</xyz>
          <limit>
            <lower>0</lower>
            <upper>0</upper>
            <effort>inf</effort>
            <velocity>inf</velocity>
            <stiffness>100000000</stiffness>
            <dissipation>1</dissipation>
          </limit>
          <dynamics>
            <spring_reference>0</spring_reference>
            <spring_stiffness>0</spring_stiffness>
            <damping>0</damping>
            <friction>0</friction>
          </dynamics>
        </axis>
      </joint>
      <joint name='caster_wheel' type='ball'>
        <parent>chassis</parent>
        <child>caster</child>
        <pose>0 0 0 0 -0 0</pose>
      </joint>
      <static>false</static>
      <self_collide>false</self_collide>
    </model>
    <light name='sun' type='directional'>
      <pose>0 0 10 0 -0 0</pose>
      <cast_shadows>true</cast_shadows>
      <intensity>1</intensity>
      <direction>-0.5 0.1 -0.9</direction>
      <diffuse>0.8 0.8 0.8 1</diffuse>
      <specular>0.2 0.2 0.2 1</specular>
      <attenuation>
        <range>1000</range>
        <linear>0.01</linear>
        <constant>0.90000000000000002</constant>
        <quadratic>0.001</quadratic>
      </attenuation>
      <spot>
        <inner_angle>0</inner_angle>
        <outer_angle>0</outer_angle>
        <falloff>0</falloff>
      </spot>
    </light>
  </world>
</sdf>
